<?xml version="1.0"?>

<robot xmlns:xacro="http://ros.org/wiki/xacro" name="wheels" >

    <!-- Wheels -->
    <!-- <xacro:property name="wheel_radius" value="0.07" /> 
    <xacro:property name="wheel_height" value="0.02" /> -->
    <!-- <xacro:property name="wheel_mass" value="2.5" /> -->
     <!-- in kg-->
    <!-- <xacro:property name="M_PI" value="3.1415926535897931" /> -->

<!--######################################################################-->
<xacro:macro name="robot_wheel" params="prefix origins rpy">

<link name="${prefix}_wheel_link">
  <visual>
    <origin xyz="0 0 0.0" rpy="1.57 0 0" /> 
    <!-- <origin xyz="0 0 0.07" rpy="-1.57 0.0 1.57" />  -->
    
    <geometry>
      <cylinder radius="0.07" length="0.02"/>
      
    </geometry>

  </visual>
  <collision>
    <origin xyz="0 0 0.0" rpy="1.57 0 0" /> 
    <geometry>
      <cylinder radius="0.07" length="0.02"/>
    
    </geometry>
  </collision>
  <inertial>
    <mass value="2.5" />
    <origin xyz="0 0 0" />
    <inertia ixx="0.001" ixy="0.0" ixz="0.0"
           iyy="0.001" iyz="0.0" 
           izz="0.001" />
  </inertial>
  </link>

  <gazebo reference="${prefix}_wheel_link">
    <mu1 value="1.0"/>
    <mu2 value="1.0"/>
    <kp  value="10000000.0" />
    <kd  value="1.0" />
    <fdir1 value="1 0 0"/>
    <material>Gazebo/Grey</material>
    <turnGravityOff>false</turnGravityOff>
  </gazebo>
  
  <joint name="${prefix}_wheel_joint" type="continuous">
    <axis xyz="0 1 0"/>
    <parent link ="base_footprint"/>
    <child link ="${prefix}_wheel_link"/>
    <origin rpy ="${rpy}" xyz= "${origins}"/>
  </joint>

<!-- 
  <gazebo reference="${prefix}_wheel_link">
    <mu1 value="1.0"/>
    <mu2 value="1.0"/>
    <kp  value="10000000.0" />
    <kd  value="1.0" />
    <fdir1 value="1 0 0"/>
    <material>Gazebo/Grey</material>
    <turnGravityOff>false</turnGravityOff>
  </gazebo>

  <transmission name="${prefix}_wheel_joint_trans">
    <type>transmission_interface/SimpleTransmission</type>
    <joint name="${prefix}_wheel_joint" />
    <actuator name="${prefix}_wheel_joint_motor">
      <hardwareInterface>EffortJointInterface</hardwareInterface>
      <mechanicalReduction>1</mechanicalReduction>
    </actuator>
  </transmission>
  -->

</xacro:macro>

<!--######################################################################-->

</robot>